<mujoco model="ant">
  <option timestep="0.01"/>
  <size njmax="3000" nconmax="3000"/>
  <default>
    <joint limited="true" stiffness="0.01"/>
    <geom condim="6" size="0.0252" rgba="1 0 0 1" type="capsule" density="5"/>
    <motor ctrllimited="true" ctrlrange="-1.0 1.0" gear=".025"/>
    <site size="0.0256" type="sphere" rgba="1 0 0 0"/>
  </default>
  <worldbody>
    <geom name="floor" size="5 5 0.05" type="plane" condim="6"/>
    <body name="robot" pos="0 0 0.132">
      <camera name="vision" pos=".125 0 .2" xyaxes="0 -1 0 .4 0 1" fovy="300"/>
      <site name="robot" pos="0 0 0"/>
      <geom name="robot" pos="0 0 0" size="0.07" type="sphere"/>
      <!-- <freejoint name="robot"/> -->
      <joint armature="0" damping="0" limited="false" margin="0.01" name="robot" pos="0 0 0" type="free"/>

      <body name="front_left_leg" pos="0 0 0">
        <geom fromto="0.0 0.0 0.0 0.075 0.075 0.0" name="aux_1_geom" size="0.025" type="capsule"/>
        <body name="aux_1" pos="0.075 0.075 0">
          <joint axis="0 0 1" name="hip_1" pos="0.0 0.0 0.0" range="-30 30" type="hinge"/>
          <geom fromto="0.0 0.0 0.0 0.05 0.05 0.0" name="left_leg_geom" size="0.025" type="capsule"/>
          <body pos="0.05 0.05 0">
            <joint axis="-1 1 0" name="ankle_1" pos="0.0 0.0 0.0" range="30 70" type="hinge"/>
            <geom fromto="0.0 0.0 0.0 0.13 0.13 0.0" name="left_ankle_geom" size="0.025" rgba="0 1 0 1" type="capsule"/>
          </body>
        </body>
      </body>
      <body name="front_right_leg" pos="0 0 0">
        <geom fromto="0.0 0.0 0.0 -0.075 0.075 0.0" name="aux_2_geom" size="0.025" type="capsule"/>
        <body name="aux_2" pos="-0.075 0.075 0">
          <joint axis="0 0 1" name="hip_2" pos="0.0 0.0 0.0" range="-30 30" type="hinge"/>
          <geom fromto="0.0 0.0 0.0 -0.05 0.05 0.0" name="right_leg_geom" size="0.025" type="capsule"/>
          <body pos="-0.05 0.05 0">
            <joint axis="1 1 0" name="ankle_2" pos="0.0 0.0 0.0" range="-70 -30" type="hinge"/>
            <geom fromto="0.0 0.0 0.0 -0.13 0.13 0.0" name="right_ankle_geom" size="0.025" rgba="0 1 0 1" type="capsule"/>
          </body>
        </body>
      </body>
      <body name="back_leg" pos="0 0 0">
        <geom fromto="0.0 0.0 0.0 -0.075 -0.075 0.0" name="aux_3_geom" size="0.025" type="capsule"/>
        <body name="aux_3" pos="-0.075 -0.075 0">
          <joint axis="0 0 1" name="hip_3" pos="0.0 0.0 0.0" range="-30 30" type="hinge"/>
          <geom fromto="0.0 0.0 0.0 -0.05 -0.05 0.0" name="back_leg_geom" size="0.025" type="capsule"/>
          <body pos="-0.05 -0.05 0">
            <joint axis="-1 1 0" name="ankle_3" pos="0.0 0.0 0.0" range="-70 -30" type="hinge"/>
            <geom fromto="0.0 0.0 0.0 -0.13 -0.13 0.0" name="third_ankle_geom" size="0.025" rgba="0 0 1 1" type="capsule"/>
          </body>
        </body>
      </body>
      <body name="right_back_leg" pos="0 0 0">
        <geom fromto="0.0 0.0 0.0 0.075 -0.075 0.0" name="aux_4_geom" size="0.025" type="capsule"/>
        <body name="aux_4" pos="0.075 -0.075 0">
          <joint axis="0 0 1" name="hip_4" pos="0.0 0.0 0.0" range="-30 30" type="hinge"/>
          <geom fromto="0.0 0.0 0.0 0.05 -0.05 0.0" name="rightback_leg_geom" size="0.025" type="capsule"/>
          <body pos="0.05 -0.05 0">
            <joint axis="1 1 0" name="ankle_4" pos="0.0 0.0 0.0" range="30 70" type="hinge"/>
            <geom fromto="0.0 0.0 0.0 0.13 -0.13 0.0" name="fourth_ankle_geom" size="0.025" rgba="0 0 1 1" type="capsule"/>
          </body>
        </body>
      </body>
    </body>
  </worldbody>
  <sensor>
    <!-- Used for observation -->
    <accelerometer site="robot" name="accelerometer"/>
    <velocimeter site="robot" name="velocimeter"/>
    <gyro site="robot" name="gyro"/>
    <magnetometer site="robot" name="magnetometer"/>

    <!-- Used for intrinsic constraints -->
    <subtreecom body="robot" name="subtreecom"/>
    <subtreelinvel body="robot" name="subtreelinvel"/>
    <subtreeangmom body="robot" name="subtreeangmom"/>
  </sensor>
  <actuator>
    <motor joint="hip_4"/>
    <motor joint="ankle_4"/>
    <motor joint="hip_1"/>
    <motor joint="ankle_1"/>
    <motor joint="hip_2"/>
    <motor joint="ankle_2"/>
    <motor joint="hip_3"/>
    <motor joint="ankle_3"/>
  </actuator>
</mujoco>
